<?xml version="1.0" encoding="utf-8"?>
<!-- This URDF was automatically created by SolidWorks to URDF Exporter! Originally created by Stephen Brawner (brawner@gmail.com) 
     Commit Version: 1.6.0-1-g15f4949  Build Version: 1.6.7594.29634
     For more information, please see http://wiki.ros.org/sw_urdf_exporter -->
<robot name="stackBot">
  <link name="base_footprint"/>
  <joint name="base_fxd" type="fixed">
  	<parent link="base_footprint"/>
  	<child link="base_link"/>
  </joint>
  <gazebo>
        <plugin name="gazebo_ros_control" filename="libgazebo_ros_control.so">
        </plugin>
  </gazebo>
  <link
    name="base_link">
    <inertial>
      <origin
        xyz="0.019327 -2.1188E-05 0.038505"
        rpy="0 0 0" />
      <mass
        value="1.043" />
      <inertia
        ixx="0.0011416"
        ixy="-3.7038E-08"
        ixz="4.9104E-09"
        iyy="0.0025437"
        iyz="-5.6302E-10"
        izz="0.0036174" />
    </inertial>
    <visual>
      <origin
        xyz="0 0 0"
        rpy="0 0 0" />
      <geometry>
        <mesh
          filename="package://stackbot_description/meshes/base_link.STL" />
      </geometry>
      <material
        name="">
        <color
          rgba="1 1 1 0.3" />
      </material>
    </visual>
    <collision>
      <origin
        xyz="0 0 0"
        rpy="0 0 0" />
      <geometry>
        <mesh
          filename="package://stackbot_description/meshes/base_link.STL" />
      </geometry>
    </collision>
  </link>
  <gazebo reference="base_link">
        <kp>100000.0</kp>
        <kd>100000.0</kd>
        <mu1>10.0</mu1>
        <mu2>10.0</mu2>
        <material>Gazebo/GreyTransparent</material>
  </gazebo>
  <link name="imu_link">
 	<inertial>
 		<origin xyz="0 0 0" rpy="0 0 0"/>
 		<mass value="0.0021"/>
 		<inertia ixx="4.897375000000001e-08" ixy="0.0" ixz="0.0" iyy="8.055775e-08" iyz="0.0" izz="1.2572000000000002e-07"/>
 	</inertial>
 	<visual>
 		<origin xyz="0 0 0" rpy="0 0 0"/>
 		<geometry>
 			<box size="0.0212 0.0164 0.0033"/>
 		</geometry>
 		<material name="">
 				<color rgba="0 0 1 0.3"/>
 		</material>
 	</visual>
 	<collision>
 		<origin xyz="0 0 0" rpy="0 0 0"/>
 		<geometry>
 			<box size="0.0212 0.0164 0.0033"/>
 		</geometry>
 	</collision>
  </link>
  <gazebo reference="imu_link">
        <kp>600000.0</kp>
        <kd>3.0</kd>
        <mu1>10.0</mu1>
        <mu2>10.0</mu2>
        <material>Gazebo/BlueTransparentOverlay</material>
  </gazebo>
  <joint name="imu_joint" type="fixed">
  	<origin xyz="0 0 0.048" rpy="0 0 0"/>
  	<parent link="base_link"/>
  	<child link="imu_link"/>
  </joint>
  <link
    name="leftWheel_Link">
    <inertial>
      <origin
        xyz="-2.2699E-06 1.496E-05 0.0002801"
        rpy="0 0 0" />
      <mass
        value="0.058225" />
      <inertia
        ixx="2.1668E-05"
        ixy="-7.1463E-09"
        ixz="7.3731E-10"
        iyy="2.1687E-05"
        iyz="-5.0354E-09"
        izz="3.9449E-05" />
    </inertial>
    <visual>
      <origin
        xyz="0 0 0"
        rpy="0 0 0" />
      <geometry>
        <mesh
          filename="package://stackbot_description/meshes/leftWheel_Link.STL" />
      </geometry>
      <material
        name="">
        <color
          rgba="1 1 1 0.85" />
      </material>
    </visual>
    <collision>
      <origin
        xyz="0 0 0"
        rpy="0 0 0" />
      <geometry>
        <mesh
          filename="package://stackbot_description/meshes/leftWheel_Link.STL" />
      </geometry>
    </collision>
  </link>
  <gazebo reference="leftWheel_Link">
        <kp>600000.0</kp>
        <kd>3.0</kd>
        <mu1>10000000.0</mu1>
        <mu2>10000000.0</mu2>
        <material>Gazebo/FlatBlack</material>
  </gazebo>
  <joint
    name="leftWheel_Joint"
    type="continuous">
    <origin
      xyz="-0.0001292 0.108 -0.018932"
      rpy="-1.5708 0 0" />
    <parent
      link="base_link" />
    <child
      link="leftWheel_Link" />
    <axis
      xyz="0 0 1" />
    <dynamics damping="1.5" friction="0.125"/>
  </joint>
  <transmission name="trans1">
        <type>transmission_interface/SimpleTransmission</type>
        <joint name="leftWheel_Joint">
            <hardwareInterface>hardware_interface/VelocityJointInterface</hardwareInterface>
        </joint>
        <actuator name="motor1">
            <hardwareInterface>hardware_interface/VelocityJointInterface</hardwareInterface>
            <mechanicalReduction>1</mechanicalReduction>
        </actuator>
  </transmission>
  <link
    name="rightWheel_link">
    <inertial>
      <origin
        xyz="-3.7028E-06 -1.4671E-05 0.0002801"
        rpy="0 0 0" />
      <mass
        value="0.058225" />
      <inertia
        ixx="2.1666E-05"
        ixy="1.6197E-09"
        ixz="1.2709E-09"
        iyy="2.1689E-05"
        iyz="4.9278E-09"
        izz="3.9449E-05" />
    </inertial>
    <visual>
      <origin
        xyz="0 0 0"
        rpy="0 0 0" />
      <geometry>
        <mesh
          filename="package://stackbot_description/meshes/rightWheel_link.STL" />
      </geometry>
      <material
        name="">
        <color
          rgba="1 1 1 0.85" />
      </material>
    </visual>
    <collision>
      <origin
        xyz="0 0 0"
        rpy="0 0 0" />
      <geometry>
        <mesh
          filename="package://stackbot_description/meshes/rightWheel_link.STL" />
      </geometry>
    </collision>
  </link>
  <gazebo reference="rightWheel_link">
        <kp>600000.0</kp>
        <kd>3.0</kd>
        <mu1>10000000.0</mu1>
        <mu2>10000000.0</mu2>
        <material>Gazebo/FlatBlack</material>
  </gazebo>
  <joint
    name="rightWheel_joint"
    type="continuous">
    <origin
      xyz="-0.00013096 -0.108 -0.018932"
      rpy="1.5708 0 0" />
    <parent
      link="base_link" />
    <child
      link="rightWheel_link" />
    <axis
      xyz="0 0 -1" />
    <dynamics damping="1.5" friction="0.125"/>
  </joint>
  <transmission name="trans2">
	<type>transmission_interface/SimpleTransmission</type>
	<joint name="rightWheel_joint">
		<hardwareInterface>hardware_interface/VelocityJointInterface</hardwareInterface>
	</joint>
	<actuator name="motor2">
		<hardwareInterface>hardware_interface/VelocityJointInterface</hardwareInterface>
		<mechanicalReduction>1</mechanicalReduction>
	</actuator>
  </transmission>
  <gazebo>
        <plugin name="gazebo_ros_imu_controller" filename="libgazebo_ros_imu.so">
            <robotNamespace>/stackBot</robotNamespace>
            <topicName>imu</topicName>
            <serviceName>imu/service</serviceName>
            <bodyName>imu_link</bodyName>
            <frameName>imu_link</frameName>
            <gaussianNoise>0</gaussianNoise>
            <rpyOffsets>0 0 0</rpyOffsets>
            <updateRate>10.0</updateRate>
            <alwaysOn>true</alwaysOn>
            <gaussianNoise>0</gaussianNoise>
            </plugin>
  </gazebo>  
  <link
    name="castorLink">
    <inertial>
      <origin
        xyz="0.0037160741706464 0.000538631212527771 -0.0145841012705388"
        rpy="0 0 0" />
      <mass
        value="0.0477277680794552" />
      <inertia
        ixx="7.73118467973946E-06"
        ixy="1.06561550753787E-08"
        ixz="1.40251589222538E-06"
        iyy="9.61400818908263E-06"
        iyz="2.03849190289507E-07"
        izz="1.27542339915242E-05" />
    </inertial>
    <visual>
      <origin
        xyz="0 0 0"
        rpy="0 0 0" />
      <geometry>
        <mesh
          filename="package://stackbot_description/meshes/castorLink.STL" />
      </geometry>
      <material
        name="">
        <color
          rgba="0.650980392156863 0.619607843137255 0.588235294117647 1" />
      </material>
    </visual>
    <collision>
      <origin
        xyz="0 0 0"
        rpy="0 0 0" />
      <geometry>
        <mesh
          filename="package://stackbot_description/meshes/castorLink.STL" />
      </geometry>
    </collision>
  </link>
  <gazebo reference="castorLink">
        <kp>600000.0</kp>
        <kd>3.0</kd>
        <mu1>0.4</mu1>
        <mu2>0.1</mu2>
        <material>Gazebo/Grey</material>
  </gazebo>
  <joint
    name="castorLink_Joint"
    type="fixed">
    <origin
      xyz="0.10885 0 0.0012"
      rpy="0 0 0" />
    <parent
      link="base_link" />
    <child
      link="castorLink" />
    <!--<axis
      xyz="0 0 -1" />-->
  </joint>
  <!--<transmission name="trans3">
	<type>transmission_interface/SimpleTransmission</type>
	<joint name="castorLink_Joint">
		<hardwareInterface>hardware_interface/VelocityJointInterface</hardwareInterface>
	</joint>
	<actuator name="motor3">
		<hardwareInterface>hardware_interface/VelocityJointInterface</hardwareInterface>
		<mechanicalReduction>1</mechanicalReduction>
	</actuator>
  </transmission>-->
  <link
    name="castorWheel">
    <inertial>
      <origin
        xyz="0.012186 -0.025419 -0.0017692"
        rpy="0 0 0" />
      <mass
        value="0.033173" />
      <inertia
        ixx="1.3903E-05"
        ixy="3.1794E-06"
        ixz="-1.3336E-07"
        iyy="1.3109E-05"
        iyz="-4.6142E-07"
        izz="1.3004E-05" />
    </inertial>
    <visual>
      <origin
        xyz="0 0 0"
        rpy="0 0 0" />
      <geometry>
        <mesh
          filename="package://stackbot_description/meshes/castorWheel.STL" />
      </geometry>
      <material
        name="">
        <color
          rgba="1 1 1 0.85" />
      </material>
    </visual>
    <collision>
      <origin
        xyz="0 0 0"
        rpy="0 0 0" />
      <geometry>
        <mesh
          filename="package://stackbot_description/meshes/castorWheel.STL" />
      </geometry>
    </collision>
  </link>
  <gazebo reference="castorWheel">
        <kp>600000.0</kp>
        <kd>3.0</kd>
        <mu1>10000000.0</mu1>
        <mu2>10000000.0</mu2>
        <material>Gazebo/White</material>
  </gazebo>
  <joint
    name="castorWheel_joint"
    type="fixed">
    <origin
      xyz="0.020613 0.0029923 -0.037824"
      rpy="1.5708 0 0" />
    <parent
      link="castorLink" />
    <child
      link="castorWheel" />
    <!--<axis
      xyz="0.14366 0 0.98963" />-->
  </joint>
  <!--<transmission name="trans4">
	<type>transmission_interface/SimpleTransmission</type>
	<joint name="castorWheel_joint">
		<hardwareInterface>hardware_interface/VelocityJointInterface</hardwareInterface>
	</joint>
	<actuator name="motor4">
		<hardwareInterface>hardware_interface/VelocityJointInterface</hardwareInterface>
		<mechanicalReduction>1</mechanicalReduction>
	</actuator>
  </transmission>-->
  <link
    name="rplidar_link">
    <inertial>
      <origin
        xyz="0.011763 -0.00073689 -0.017188"
        rpy="0 0 0" />
      <mass
        value="0.078925" />
      <inertia
        ixx="2.1052E-05"
        ixy="-2.5865E-08"
        ixz="-4.4884E-07"
        iyy="2.503E-05"
        iyz="1.5472E-08"
        izz="4.3747E-05" />
    </inertial>
    <visual>
      <origin
        xyz="0 0 0"
        rpy="0 0 0" />
      <geometry>
        <mesh
          filename="package://stackbot_description/meshes/rplidar_link.STL" />
      </geometry>
      <material
        name="">
        <color
          rgba="0.75294 0.75294 0.75294 1" />
      </material>
    </visual>
    <collision>
      <origin
        xyz="0 0 0"
        rpy="0 0 0" />
      <geometry>
        <mesh
          filename="package://stackbot_description/meshes/rplidar_link.STL" />
      </geometry>
    </collision>
  </link>
  <gazebo reference="rplidar_link">
        <kp>100000.0</kp>
        <kd>100000.0</kd>
        <mu1>10.0</mu1>
        <mu2>10.0</mu2>
        <material>Gazebo/Black</material>
  </gazebo>
  <joint
    name="rplidar_joint"
    type="fixed">
    <origin
      xyz="-0.00013 0 0.19235"
      rpy="0 0 0" />
    <parent
      link="base_link" />
    <child
      link="rplidar_link" />
    <axis
      xyz="0 0 0" />
  </joint>
  <gazebo reference="rplidar_link">
    <sensor type="ray" name="head_rplidar_sensor">
      <pose>0 0 0 0 0 0</pose>
      <visualize>true</visualize>
      <update_rate>40</update_rate>
      <ray>
        <scan>
          <horizontal>
            <samples>720</samples>
            <resolution>1</resolution>
            <min_angle>-3.14159265</min_angle>
            <max_angle>3.14159265</max_angle>
          </horizontal>
        </scan>
        <range>
          <min>0.2</min>
          <max>12.0</max>
          <resolution>0.01</resolution>
        </range>
        <noise>
          <type>gaussian</type>
          <mean>0.0</mean>
          <stddev>0.01</stddev>
        </noise>
      </ray>
      <plugin name="gazebo_ros_head_rplidar_controller" filename="libgazebo_ros_laser.so">
        <topicName>scan</topicName>
        <frameName>rplidar_link</frameName>
      </plugin>
    </sensor>
  </gazebo> 
</robot>
